Workbook

Sheet Sheet1
A1: Summary Worksheet
B3: COP ALPHA | C3: -0.00011507642 | E3: AAPLE BETA | F3: 0.90008643
B4: WFC ALPHA | C4: 3.1818693e-05 | E4: GOOG BETA | F4: 0.97271782
B5: XOM ALPHA | C5: 6.1424473e-05 | E5: XOM BETA | F5: 1.0151406
B6: TTM ALPHA | C6: 0.00015327263 | E6: MSFT BETA | F6: 1.0434897
B7: MSFT ALPHA | C7: 0.00028448409 | E7: DIS BETA | F7: 1.1295707
B8: BIDU ALPHA | C8: 0.00031565585 | E8: COP BETA | F8: 1.1685959
B9: DIS ALPHA | C9: 0.00039710933 | E9: TSLA BETA | F9: 1.239124
B10: AAPL ALPHA | C10: 0.00044039568 | E10: BIDU BETA | F10: 1.3122063
B11: GOOG ALPHA | C11: 0.00044716465 | E11: WFC BETA | F11: 1.3397083
B12: TSLA ALPHA | C12: 0.0014789919 | E12: TTM BETA | F12: 1.4927608

Sheet Portfolio 1
A1: Microsoft & WFC:
A3: 3 | B3: Microsoft: | C3: WFC | F3: Weight Mic | G3: Weight wfc | H3: Expected return | I3: Variance | J3: STD | K3: Column 1
A4: Average Return | B4: 0.00074693549 | C4: 0.00062554756 | F4: 0.55 | G4: 0.45 | H4: =($B$4*F4)+($C$4*G4) -> 0.00069231092 | I4: =(F4^2*$B$6)+(G4^2*$C$6)+(2*F4*G4*$D$13) -> 0.00017233058 | J4: =SQRT(I4) -> 0.013127474
A5: STD.DEV | B5: 0.014813012 | C5: 0.015640826 | F5: 0.6 | G5: 0.4 | H5: =($B$4*F5)+($C$4*G5) -> 0.00069838032 | I5: =(F5^2*$B$6)+(G5^2*$C$6)+(2*F5*G5*$D$13) -> 0.00017284096 | J5: =SQRT(I5) -> 0.013146899
A6: Variance | B6: =B5^2 -> 0.00021942533 | C6: =C5^2 -> 0.00024463544 | F6: 0.5 | G6: 0.5 | H6: =($B$4*F6)+($C$4*G6) -> 0.00068624152 | I6: =(F6^2*$B$6)+(G6^2*$C$6)+(2*F6*G6*$D$13) -> 0.00017300079 | J6: =SQRT(I6) -> 0.013152976
F7: 0.65 | G7: 0.35 | H7: =($B$4*F7)+($C$4*G7) -> 0.00070444971 | I7: =(F7^2*$B$6)+(G7^2*$C$6)+(2*F7*G7*$D$13) -> 0.00017453194 | J7: =SQRT(I7) -> 0.013211054
F8: 0.45 | G8: 0.55 | H8: =($B$4*F8)+($C$4*G8) -> 0.00068017213 | I8: =(F8^2*$B$6)+(G8^2*$C$6)+(2*F8*G8*$D$13) -> 0.00017485159 | J8: =SQRT(I8) -> 0.013223146
F9: 0.7 | G9: 0.3 | H9: =($B$4*F9)+($C$4*G9) -> 0.00071051911 | I9: =(F9^2*$B$6)+(G9^2*$C$6)+(2*F9*G9*$D$13) -> 0.0001774035 | J9: =SQRT(I9) -> 0.013319291
F10: 0.4 | G10: 0.6 | H10: =($B$4*F10)+($C$4*G10) -> 0.00067410273 | I10: =(F10^2*$B$6)+(G10^2*$C$6)+(2*F10*G10*$D$13) -> 0.00017788298 | J10: =SQRT(I10) -> 0.013337278
F11: 0.75 | G11: 0.25 | H11: =($B$4*F11)+($C$4*G11) -> 0.00071658851 | I11: =(F11^2*$B$6)+(G11^2*$C$6)+(2*F11*G11*$D$13) -> 0.00018145566 | J11: =SQRT(I11) -> 0.013470548
B12: Adj R Msft | C12: Adj R WFC | D12: Covariance | F12: 0.35 | G12: 0.65 | H12: =($B$4*F12)+($C$4*G12) -> 0.00066803333 | I12: =(F12^2*$B$6)+(G12^2*$C$6)+(2*F12*G12*$D$13) -> 0.00018209497 | J12: =SQRT(I12) -> 0.013494257
B13: 0.0065188837 | C13: -0.016406292 | D13: =_xlfn.COVARIANCE.S(B13:B1523,C13:C1523) -> 0.00011397119 | F13: 0.8 | G13: 0.2 | H13: =($B$4*F13)+($C$4*G13) -> 0.0007226579 | I13: =(F13^2*$B$6)+(G13^2*$C$6)+(2*F13*G13*$D$13) -> 0.00018668841 | J13: =SQRT(I13) -> 0.013663397
B14: 0.004749614 | C14: -0.011914262 | F14: 0.3 | G14: 0.7 | H14: =($B$4*F14)+($C$4*G14) -> 0.00066196394 | I14: =(F14^2*$B$6)+(G14^2*$C$6)+(2*F14*G14*$D$13) -> 0.00018748755 | J14: =SQRT(I14) -> 0.013692609
B15: 0.023635556 | C15: 0.010852135 | F15: 0.85 | G15: 0.15 | H15: =($B$4*F15)+($C$4*G15) -> 0.0007287273 | I15: =(F15^2*$B$6)+(G15^2*$C$6)+(2*F15*G15*$D$13) -> 0.00019310175 | J15: =SQRT(I15) -> 0.013896106
B16: 0.020151098 | C16: 0.060039782 | F16: 0.25 | G16: 0.75 | H16: =($B$4*F16)+($C$4*G16) -> 0.00065589454 | I16: =(F16^2*$B$6)+(G16^2*$C$6)+(2*F16*G16*$D$13) -> 0.00019406071 | J16: =SQRT(I16) -> 0.013930568
B17: 0.0045267926 | C17: -0.00075024525 | F17: 0.9 | G17: 0.1 | H17: =($B$4*F17)+($C$4*G17) -> 0.0007347967 | I17: =(F17^2*$B$6)+(G17^2*$C$6)+(2*F17*G17*$D$13) -> 0.00020069569 | J17: =SQRT(I17) -> 0.014166711
B18: -0.0057353261 | C18: 0.013513555 | F18: 0.2 | G18: 0.8 | H18: =($B$4*F18)+($C$4*G18) -> 0.00064982514 | I18: =(F18^2*$B$6)+(G18^2*$C$6)+(2*F18*G18*$D$13) -> 0.00020181448 | J18: =SQRT(I18) -> 0.014206142
B19: 0.023073688 | C19: 0.0022222218 | F19: 0.95 | G19: 0.05 | H19: =($B$4*F19)+($C$4*G19) -> 0.00074086609 | I19: =(F19^2*$B$6)+(G19^2*$C$6)+(2*F19*G19*$D$13) -> 0.00020947021 | J19: =SQRT(I19) -> 0.014473086
B20: 0.012082167 | C20: 0.032520348 | F20: 0.15 | G20: 0.85 | H20: =($B$4*F20)+($C$4*G20) -> 0.00064375575 | I20: =(F20^2*$B$6)+(G20^2*$C$6)+(2*F20*G20*$D$13) -> 0.00021074883 | J20: =SQRT(I20) -> 0.014517191
B21: 0.01233587 | C21: -0.0100215 | F21: 1 | G21: -1.9984014e-15 | H21: =($B$4*F21)+($C$4*G21) -> 0.00074693549 | I21: =(F21^2*$B$6)+(G21^2*$C$6)+(2*F21*G21*$D$13) -> 0.00021942533 | J21: =SQRT(I21) -> 0.014813012
B22: 0.002751582 | C22: 0.0054229926 | F22: 0.1 | G22: 0.9 | H22: =($B$4*F22)+($C$4*G22) -> 0.00063768635 | I22: =(F22^2*$B$6)+(G22^2*$C$6)+(2*F22*G22*$D$13) -> 0.00022086377 | J22: =SQRT(I22) -> 0.014861486
B23: -0.024304226 | C23: -0.056454531 | F23: 0.05 | G23: 0.95 | H23: =($B$4*F23)+($C$4*G23) -> 0.00063161695 | I23: =(F23^2*$B$6)+(G23^2*$C$6)+(2*F23*G23*$D$13) -> 0.00023215931 | J23: =SQRT(I23) -> 0.015236775 | O23: Msft | P23: wfc
B24: 0.013660098 | C24: -0.0083840863 | F24: 0 | G24: 1 | H24: =($B$4*F24)+($C$4*G24) -> 0.00062554756 | I24: =(F24^2*$B$6)+(G24^2*$C$6)+(2*F24*G24*$D$13) -> 0.00024463544 | J24: =SQRT(I24) -> 0.015640826 | K24: =MIN(Table1[STD]) -> 0.013127474 | M24: Min Variance Weights= | O24: 0.55 | P24: 0.45
B25: 0.0099088536 | C25: -0.0042275757
B26: -0.014128692 | C26: 0.0057892697
B27: 0.028662393 | C27: 0.051036093 | L27: =MIN(Table1[Variance]) -> 0.00017233058
B28: -0.0011610143 | C28: 0.0010952901
B29: 0.011236001 | C29: 0.017870151
B30: 0.002298807 | C30: 0.017198134
B31: -0.0080274612 | C31: -0.011271546
B32: 0.0030828234 | C32: -0.013537555 | G32: Msft | H32: wfc
B33: -0.0084518224 | C33: 0.0014445088 | F33: weight = | G33: 0.55338447 | H33: =1-G33 -> 0.44661553 | J33: 1
B34: 0.020147275 | C34: 0.030292098 | F34: Variance | G34: =(G33^2*B6)+(H33^2*C6)+(2*G33*H33*D13) -> 0.00017232787 | J34: 0
B35: -0.0064565551 | C35: -0.015750745 | F35: Std | G35: =SQRT(G34) -> 0.013127371
B36: -0.016437283 | C36: -0.0049875606 | F36: Expected Return = | G36: =(G33*B4)+(H33*C4) -> 0.00069272175
B37: -0.013991414 | C37: -0.0017902447 | F37: Sharpe Ratio: | G37: =(G36-0)/G35 | K37: MinimumRisk:
B38: 0.0070949059 | C38: -0.004662777 | G38: =(G36-0)/G35 -> 0.052769267 | L38: Msft | M38: wfc
B39: 0.0023484305 | C39: 0.017297287 | K39: weight = | L39: 0.55338447 | M39: 0.44661553
B40: -0.021085573 | C40: -0.01629469 | K40: Variance | L40: 0.00017232787
B41: -0.0083765282 | C41: -0.052934864 | K41: Std | L41: 0.013127371
...

Sheet Full Portfolio
A1: 10 Asset Potfolio: | B1: Adj Returns:
B2: Aapl | C2: Bidu | D2: Msft | E2: Cop | F2: Dis | G2: Goog | H2: Tsla | I2: Ttm | J2: Wfc | K2: Xom
B3: -0.012125807 | C3: 0.0069036573 | D3: 0.0065188837 | E3: -0.0044815707 | F3: -0.00031746476 | G3: -0.012271026 | H3: -0.078472556 | I3: 0.011052902 | J3: -0.016406292 | K3: -0.008060274
B4: -0.006197722 | C4: -0.014587891 | D4: 0.004749614 | E4: -0.0010232382 | F4: -0.0034931867 | G4: -0.0066896311 | H4: -0.12568297 | I4: -0.012658201 | J4: -0.011914262 | K4: -0.00070660504 | M4: Covariance Matrix:
B5: 0.0068437567 | C5: -0.0014804737 | D5: 0.023635556 | E5: 0.0077837007 | F5: 0.010834939 | G5: -0.0010994678 | H5: -0.16093749 | I5: 0.0064103046 | J5: 0.010852135 | K5: 0.015732713 | N5: Aapl | O5: Bidu | P5: Msft | Q5: Cop | R5: Dis | S5: Goog | T5: Tsla | U5: Ttm | V5: Wfc | W5: Xom
B6: 0.04038137 | C6: 0.072943013 | D6: 0.020151098 | E6: 0.039837604 | F6: 0.044766682 | G6: 0.032402993 | H6: -0.019242767 | I6: 0.0017370002 | J6: 0.060039782 | K6: 0.016881334 | M6: Aapl | N6: =VARP('Full Portfolio'!$B$3:$B$1513) -> 0.00027260181 | O6: 0.00014020363 | P6: 9.1197689e-05 | Q6: 8.6396286e-05 | R6: 7.9833364e-05 | S6: 0.00010334608 | T6: 0.00012384515 | U6: 0.00012624627 | V6: 9.953054e-05 | W6: 6.7677521e-05
B7: -0.0022423051 | C7: 0.00082903133 | D7: 0.0045267926 | E7: 0.0076231097 | F7: 0.0060350547 | G7: 0.01412711 | H7: 0.10506323 | I7: 0.015028926 | J7: -0.00075024525 | K7: 0.0065035149 | M7: Bidu | N7: 0.00014020363 | O7: =VARP('Full Portfolio'!$C$3:$C$1513) -> 0.00062161449 | P7: 0.0001261591 | Q7: 0.00013579362 | R7: 0.00013076058 | S7: 0.00017083205 | T7: 0.00021329347 | U7: 0.00022128157 | V7: 0.00015476754 | W7: 9.8042449e-05
B8: 0.0059281733 | C8: -0.016981955 | D8: -0.0057353261 | E8: 0.014549026 | F8: 0.012297516 | G8: 0.023939842 | H8: -0.003436369 | I8: 0.0051253069 | J8: 0.013513555 | K8: -0.00051015912 | M8: Msft | N8: 9.1197689e-05 | O8: 0.0001261591 | P8: =VARP('Full Portfolio'!$D$3:$D$1513) -> 0.00021942533 | Q8: 9.5832082e-05 | R8: 9.3516874e-05 | S8: 0.00010777572 | T8: 0.00011421713 | U8: 0.00013382218 | V8: 0.00011389576 | W8: 8.1578374e-05
B9: -0.0089746265 | C9: -0.0066010396 | D9: 0.023073688 | E9: -0.0038242342 | F9: 0.00059260089 | G9: 0.017839983 | H9: -0.020115 | I9: 0.0090651143 | J9: 0.0022222218 | K9: 0.002722016 | M9: Cop | N9: 8.6396286e-05 | O9: 0.00013579362 | P9: 9.5832082e-05 | Q9: =VARP('Full Portfolio'!$E$3:$E$1513) -> 0.00028082163 | R9: 0.00010160881 | S9: 8.6662554e-05 | T9: 0.00014026915 | U9: 0.0001565238 | V9: 0.00013173708 | W9: 0.00014321481
B10: -0.021337814 | C10: 0.051604607 | D10: 0.012082167 | E10: 0.021497304 | F10: 0.020136239 | G10: 0.028098257 | H10: 0.063929623 | I10: 0.039865318 | J10: 0.032520348 | K10: 0.0081438803 | M10: Dis | N10: 7.9833364e-05 | O10: 0.00013076058 | P10: 9.3516874e-05 | Q10: 0.00010160881 | R10: =VARP('Full Portfolio'!$F$3:$F$1513) -> 0.00018848503 | S10: 9.1763337e-05 | T10: 0.00013156761 | U10: 0.00013940383 | V10: 0.00013132847 | W10: 8.8054013e-05
B11: 0.0036934377 | C11: 0.0087389356 | D11: 0.01233587 | E11: -0.0078920099 | F11: -0.0060957811 | G11: 0.0043745099 | H11: 0.093715606 | I11: -0.02807774 | J11: -0.0100215 | K11: -0.0026926978 | M11: Goog | N11: 0.00010334608 | O11: 0.00017083205 | P11: 0.00010777572 | Q11: 8.6662554e-05 | R11: 9.1763337e-05 | S11: =VARP('Full Portfolio'!$G$3:$G$1513) -> 0.00025577447 | T11: 0.00013473204 | U11: 0.00011886448 | V11: 0.00010798853 | W11: 7.4676417e-05
B12: -0.005064686 | C12: 0.0081300814 | D12: 0.002751582 | E12: 0.0011364349 | F12: -0.005549111 | G12: 0.0054544525 | H12: 0.0025201109 | I12: 0.0083333096 | J12: 0.0054229926 | K12: 0.00016878168 | M12: Tsla | N12: 0.00012384515 | O12: 0.00021329347 | P12: 0.00011421713 | Q12: 0.00014026915 | R12: 0.00013156761 | S12: 0.00013473204 | T12: =VARP('Full Portfolio'!$H$3:$H$1513) -> 0.0011700999 | U12: 0.00022268576 | V12: 0.0001369636 | W12: 9.7438987e-05
B13: -0.0061642271 | C13: -0.027895294 | D13: -0.024304226 | E13: -0.019107078 | F13: -0.029955982 | G13: -0.069653028 | H13: 0.037707393 | I13: -0.004407752 | J13: -0.056454531 | K13: -0.022102278 | M13: Ttm | N13: 0.00012624627 | O13: 0.00022128157 | P13: 0.00013382218 | Q13: 0.0001565238 | R13: 0.00013940383 | S13: 0.00011886448 | T13: 0.00022268576 | U13: =VARP('Full Portfolio'!$I$3:$I$1513) -> 0.00061625395 | V13: 0.00017284956 | W13: 0.00011869148
B14: -0.017286892 | C14: -0.0085678908 | D14: 0.013660098 | E14: -0.00019282743 | F14: 0.008477228 | G14: 0.014294737 | H14: 0.061531059 | I14: 0.011068136 | J14: -0.0083840863 | K14: 0.0081090727 | M14: Wfc | N14: 9.953054e-05 | O14: 0.00015476754 | P14: 0.00011389576 | Q14: 0.00013173708 | R14: 0.00013132847 | S14: 0.00010798853 | T14: 0.0001369636 | U14: 0.00017284956 | V14: =VARP('Full Portfolio'!$J$3:$J$1513) -> 0.00024463544 | W14: 0.00011024513
B15: 0.02569426 | C15: 0.015637846 | D15: 0.0099088536 | E15: 0.015817885 | F15: 0.0027018963 | G15: 0.033055884 | H15: -0.073482474 | I15: 0.00054732825 | J15: -0.0042275757 | K15: 0.0088995382 | M15: Xom | N15: 6.7677521e-05 | O15: 9.8042449e-05 | P15: 8.1578374e-05 | Q15: 0.00014321481 | R15: 8.8054013e-05 | S15: 7.4676417e-05 | T15: 9.7438987e-05 | U15: 0.00011869148 | V15: 0.00011024513 | W15: =VARP('Full Portfolio'!$K$3:$K$1513) -> 0.00014332868
B16: 0.00932941 | C16: -0.0098595758 | D16: -0.014128692 | E16: -0.01025437 | F16: -0.017664688 | G16: -0.0084927197 | H16: -0.0039408869 | I16: -0.010940927 | J16: 0.0057892697 | K16: -0.013231593
B17: 0.018801171 | C17: 0.015550389 | D17: 0.028662393 | E17: 0.022064344 | F17: 0.023773206 | G17: 0.015308926 | H17: 0.038575719 | I17: 0.042035382 | J17: 0.051036093 | K17: 0.020801158
B18: 0.0035518192 | C18: 0.048488934 | D18: -0.0011610143 | E18: 0.0097616662 | F18: 0.016076243 | G18: 0.010828947 | H18: 0.013809571 | I18: 0.0015924202 | J18: 0.0010952901 | K18: 0.0057258245 | M18: No Short Selling Portfolio
B19: -0.0025390012 | C19: 0.029592686 | D19: 0.011236001 | E19: 0.011898084 | F19: 0.0079109434 | G19: -0.0022241706 | H19: -0.015969938 | I19: 0.010598785 | J19: 0.017870151 | K19: 0.01121899 | M19: Asset | N19: Mean | O19: Weight | P19: Expected Return | Q19: Stdev Individual | R19: Variance Indiv | S19: Variance Portfolio | T19: stdeV | U19: Sharpe Ratio
B20: 0.018512813 | C20: 0.0087096799 | D20: 0.002298807 | E20: 0.00018368734 | F20: -0.0034884525 | G20: 0.0074851177 | H20: -0.019093173 | I20: -0.0052438983 | J20: 0.017198134 | K20: 0.0069548349 | M20: Aapl | N20: 0.00083929393 | O20: 0.17074723 | P20: =N20*O20 -> 0.00014330711 | Q20: 0.016510658 | R20: =Q20^2 -> 0.00027260181 | U20: =(Q30-0)/T21 -> 0.084187616
B21: -0.011814679 | C21: -0.020599457 | D21: -0.0080274612 | E21: 0 | F21: -0.007001106 | G21: -0.016807753 | H21: 0.0082725065 | I21: 0.014233061 | J21: -0.011271546 | K21: 0.0016444455 | M21: Bidu | N21: 0.00089719644 | O21: 0 | P21: =N21*O21 -> 0 | Q21: 0.024932198 | R21: =Q21^2 -> 0.00062161449 | S21: {=MMULT(TRANSPOSE(O20:O29),MMULT(N6:W15,O20:O29))} -> 0.00015813288 | T21: =SQRT(S21) -> 0.01257509
B22: -0.010921189 | C22: -0.0025189546 | D22: 0.0030828234 | E22: 0.012432719 | F22: -0.0096945164 | G22: 0.0013213467 | H22: -0.017857095 | I22: -0.0072765015 | J22: -0.013537555 | K22: -0.0093580786 | M22: Msft | N22: 0.00074693549 | O22: 0.099127207 | P22: =N22*O22 -> 7.4041629e-05 | Q22: 0.014813012 | R22: =Q22^2 -> 0.00021942533 | S22: {=MMULT(MMULT(TRANSPOSE(O20:O29),N6:W15),O20:O29)} -> 0.00015813288
B23: -0.0033319083 | C23: 0.02790413 | D23: -0.0084518224 | E23: 0.012096753 | F23: -0.00059330407 | G23: -0.00028864432 | H23: -0.020147371 | I23: -0.009947668 | J23: 0.0014445088 | K23: -0.010938012 | M23: Cop | N23: 0.00040281925 | O23: 0 | P23: =N23*O23 -> 0 | Q23: 0.016757733 | R23: =Q23^2 -> 0.00028082163
B24: 0.017881435 | C24: 0.0391843 | D24: 0.020147275 | E24: 0.041832703 | F24: 0.0234491 | G24: 0.01146742 | H24: 0.04914739 | I24: 0.025912196 | J24: 0.030292098 | K24: 0.037868604 | M24: Dis | N24: 0.0008977099 | O24: 0.38795409 | P24: =N24*O24 -> 0.00034827023 | Q24: 0.013728985 | R24: =Q24^2 -> 0.00018848503
B25: 0.00030552342 | C25: 0.0022458984 | D25: -0.0064565551 | E25: 0.00052145694 | F25: -0.0078306413 | G25: -0.0011826562 | H25: 0.049235229 | I25: 0.0030927419 | J25: -0.015750745 | K25: 0.01259289 | M25: Goog | N25: 0.00087825152 | O25: 0.17473389 | P25: =N25*O25 -> 0.0001534603 | Q25: 0.015992951 | R25: =Q25^2 -> 0.00025577447
B26: 0.0040087411 | C26: 0.021346821 | D26: -0.016437283 | E26: -0.0024321588 | F26: 0.018123451 | G26: 0.033664707 | H26: -0.031435124 | I26: -0.0077080981 | J26: -0.0049875606 | K26: 0 | M26: Tsla | N26: 0.0020281441 | O26: 0.16743758 | P26: =N26*O26 -> 0.00033958754 | Q26: 0.034206723 | R26: =Q26^2 -> 0.0011700999
B27: -0.0048672829 | C27: -0.011893742 | D27: -0.013991414 | E27: 0.0048763513 | F27: 0.0043065669 | G27: 0.0035156092 | H27: -0.038099671 | I27: 0.0041429675 | J27: -0.0017902447 | K27: -0.00015948955 | M27: Ttm | N27: 0.00081483095 | O27: 0 | P27: =N27*O27 -> 0 | Q27: 0.024824463 | R27: =Q27^2 -> 0.00061625395
B28: -0.0061520666 | C28: 0.011218873 | D28: 0.0070949059 | E28: -0.013344964 | F28: 0.0005717633 | G28: -0.015508779 | H28: -0.042053837 | I28: 0.04195078 | J28: -0.004662777 | K28: -0.011800318 | M28: Wfc | N28: 0.00062554756 | O28: 0 | P28: =N28*O28 -> 0 | Q28: 0.015640826 | R28: =Q28^2 -> 0.00024463544
B29: 0.0063823346 | C29: 0.011903375 | D29: 0.0023484305 | E29: 0.006674783 | F29: 0.0045714302 | G29: 0.01025548 | H29: 0.00051046452 | I29: 0.0095620832 | J29: 0.017297287 | K29: 0.0077456881 | M29: Xom | N29: 0.00051131218 | O29: 0 | P29: =N29*O29 -> 0 | Q29: 0.011971996 | R29: =Q29^2 -> 0.00014332868 | T29: =T21*100 -> 1.257509
B30: -0.008939829 | C30: 0.0035404866 | D30: -0.021085573 | E30: -0.0076775304 | F30: 0.0036974041 | G30: -0.0032452866 | H30: -0.029081582 | I30: 0.030408807 | J30: -0.01629469 | K30: -0.0083266805 | O30: =SUM(O20:O29) -> 1 | P30: =SUM(P20:P29) -> 0.0010586668 | Q30: =SUMPRODUCT(N20:N29,O20:O29) -> 0.0010586668
B31: -0.035542187 | C31: -0.041424831 | D31: -0.0083765282 | E31: -0.023914206 | F31: -0.030320195 | G31: -0.023763657 | H31: -0.059379976 | I31: 0.041606177 | J31: -0.052934864 | K31: -0.017889043 | O31: 1
B32: 0.0063951835 | C32: -0.018758173 | D32: -0.014883365 | E32: -0.0028822878 | F32: -0.006721182 | G32: 0.0005490488 | H32: -0.016759777 | I32: 0.01439849 | J32: -0.011406843 | K32: -0.002649448
B33: -0.01068359 | C33: 0.0021778584 | D33: -0.003674948 | E33: -0.0059619439 | F33: -0.0091203924 | G33: -0.011503813 | H33: 0.040909091 | I33: -0.013278422 | J33: -0.0061538129 | K33: -0.005312953
B34: -0.0058610129 | C34: 0.01835079 | D34: 0.0040983474 | E34: -0.0016358277 | F34: -0.00059383254 | G34: -0.001562677 | H34: 0.025109225 | I34: 0.018097534 | J34: -0.0061919615 | K34: -0.00050074307
B35: 0.017485068 | C35: 0.0009484529 | D35: 0.013951557 | E35: 0.01711273 | F35: 0.0029708297 | G35: 0.010152595 | H35: 0.019701756 | I35: 0.036007238 | J35: -0.013239877 | K35: 0.015698052 | O35: 0.17473389 | P35: =O35*100 -> 17.473389
B36: 0.0043656099 | C36: -0.017884662 | D36: 0.0044516652 | E36: -0.008054553 | F36: 0.0044431904 | G36: -0.017063523 | H36: -0.019843342 | I36: -0.010558719 | J36: 0.0015784892 | K36: -0.011016097
B37: -0.012605233 | C37: -0.020863435 | D37: -0.015310233 | E37: -0.012811152 | F37: -0.021232715 | G37: -0.02940993 | H37: 0.0010655834 | I37: -0.021787451 | J37: -0.037431015 | K37: -0.014297587
B38: -0.00096047669 | C38: 0.012070402 | D38: -0.0085924825 | E38: -0.014988111 | F38: -0.0042181315 | G38: -0.012714456 | H38: 0.016498083 | I38: 0.030909112 | J38: 0.0069586818 | K38: -0.0067465368
B39: -0.015382188 | C39: -0.034075637 | D39: 0.0020635741 | E39: -0.0033402886 | F39: -0.0036308142 | G39: 0.0044370036 | H39: 0.053926649 | I39: -0.016313976 | J39: -0.015040689 | K39: 0.010358315
B40: -0.023881162 | C40: -0.025576501 | D40: -0.0098846709 | E40: -0.0052131535 | F40: -0.02399032 | G40: -0.027323421 | H40: -0.046199605 | I40: -0.009412795 | J40: -0.024350012 | K40: -0.0094117843
...

Sheet Apple
A1: Date | B1: Open | C1: High | D1: Low | E1: Close | F1: Volume | G1: Adj Close | I1: Appls Adj Return | J1: Dji Adj Return
A2: 40359 | B2: 256.70999 | C2: 257.96999 | D2: 250.01 | E2: 251.53 | F2: 184863000 | G2: 33.075655 | I2: AAPL | J2: DJI
A3: 40360 | B3: 254.3 | C3: 254.80001 | D3: 243.22001 | E3: 248.48 | F3: 255724000 | G3: 32.674586 | H3: =(E3-E2)/E2 -> -0.012125802 | I3: =(G3-G2)/G2 -> -0.012125807 | J3: -0.0042448511 | L3: SUMMARY OUTPUT
A4: 40361 | B4: 250.49 | C4: 250.92999 | D4: 243.20001 | E4: 246.93999 | F4: 173460700 | G4: 32.472078 | H4: =(E4-E3)/E3 -> -0.0061977181 | I4: =(G4-G3)/G3 -> -0.006197722 | J4: -0.0047315346
A5: 40365 | B5: 251 | C5: 252.79999 | D5: 246.16 | E5: 248.62999 | F5: 153808900 | G5: 32.694309 | H5: =(E5-E4)/E4 -> 0.0068437639 | I5: =(G5-G4)/G4 -> 0.0068437567 | J5: 0.0058989071 | L5: Regression Statistics
A6: 40366 | B6: 250.49 | C6: 258.77001 | D6: 249.74999 | E6: 258.67001 | F6: 163639000 | G6: 34.01455 | H6: =(E6-E5)/E5 -> 0.040381355 | I6: =(G6-G5)/G5 -> 0.04038137 | J6: 0.028188717 | L6: Multiple R | M6: 0.49649556
A7: 40367 | B7: 262.48 | C7: 262.90001 | D7: 254.89 | E7: 258.08999 | F7: 184536100 | G7: 33.938279 | H7: =(E7-E6)/E6 -> -0.0022422894 | I7: =(G7-G6)/G6 -> -0.0022423051 | J7: 0.01204897 | L7: R Square | M7: 0.24650784
A8: 40368 | B8: 256.88999 | C8: 259.89999 | D8: 255.15999 | E8: 259.61999 | F8: 108330600 | G8: 34.139471 | H8: =(E8-E7)/E7 -> 0.0059281415 | I8: =(G8-G7)/G7 -> 0.0059281733 | J8: 0.005823069 | L8: Adjusted R Square | M8: 0.24600851
A9: 40371 | B9: 258.53 | C9: 261.85 | D9: 254.86001 | E9: 257.29 | F9: 140719600 | G9: 33.833082 | H9: =(E9-E8)/E8 -> -0.0089746018 | I9: =(G9-G8)/G8 -> -0.0089746265 | J9: 0.0017885081 | L9: Standard Error | M9: 0.014341393
A10: 40372 | B10: 256.31999 | C10: 256.39999 | D10: 246.42999 | E10: 251.79999 | F10: 297731000 | G10: 33.111158 | H10: =(E10-E9)/E9 -> -0.021337813 | I10: =(G10-G9)/G9 -> -0.021337814 | J10: 0.014364343 | L10: Observations | M10: 1511
A11: 40373 | B11: 249.37999 | C11: 255.80001 | D11: 249.00001 | E11: 252.73 | F11: 203011900 | G11: 33.233452 | H11: =(E11-E10)/E10 -> 0.0036934393 | I11: =(G11-G10)/G10 -> 0.0036934377 | J11: 0.00035705809
A12: 40374 | B12: 248.23001 | C12: 256.96999 | D12: 247.3 | E12: 251.45 | F12: 206216500 | G12: 33.065135 | H12: =(E12-E11)/E11 -> -0.0050647014 | I12: =(G12-G11)/G11 -> -0.005064686 | J12: -0.00071480277 | L12: ANOVA
A13: 40375 | B13: 253.18 | C13: 254.97 | D13: 248.41001 | E13: 249.9 | F13: 259964600 | G13: 32.861314 | H13: =(E13-E12)/E12 -> -0.0061642314 | I13: =(G13-G12)/G12 -> -0.0061642271 | J13: -0.025234228 | M13: df | N13: SS | O13: MS | P13: F | Q13: Significance F
A14: 40378 | B14: 249.88001 | C14: 249.88001 | D14: 239.60001 | E14: 245.58001 | F14: 256119500 | G14: 32.293244 | H14: =(E14-E13)/E13 -> -0.017286882 | I14: =(G14-G13)/G13 -> -0.017286892 | J14: 0.0055981241 | L14: Regression | M14: 1 | N14: 0.10153691 | O14: 0.10153691 | P14: 493.67511 | Q14: 7.4411992e-95
A15: 40379 | B15: 242.9 | C15: 252.89999 | D15: 240.01001 | E15: 251.89001 | F15: 268737700 | G15: 33.122995 | H15: =(E15-E14)/E14 -> 0.025694265 | I15: =(G15-G14)/G14 -> 0.02569426 | J15: 0.0074381597 | L15: Residual | M15: 1509 | N15: 0.31036443 | O15: 0.00020567557
A16: 40380 | B16: 265.08999 | C16: 265.14999 | D16: 253.99999 | E16: 254.24 | F16: 296417800 | G16: 33.432013 | H16: =(E16-E15)/E15 -> 0.0093294172 | I16: =(G16-G15)/G15 -> 0.00932941 | J16: -0.010696981 | L16: Total | M16: 1510 | N16: 0.41190134
A17: 40381 | B17: 257.68 | C17: 260 | D17: 255.31001 | E17: 259.02 | F17: 161329700 | G17: 34.060574 | H17: =(E17-E16)/E16 -> 0.018801141 | I17: =(G17-G16)/G16 -> 0.018801171 | J17: 0.019936657
A18: 40382 | B18: 257.09 | C18: 260.38 | D18: 256.27999 | E18: 259.94 | F18: 133347200 | G18: 34.181551 | H18: =(E18-E17)/E17 -> 0.00355183 | I18: =(G18-G17)/G17 -> 0.0035518192 | J18: 0.0099125497 | M18: Coefficients | N18: Standard Error | O18: t Stat | P18: P-value | Q18: Lower 95% | R18: Upper 95% | S18: Lower 95.0% | T18: Upper 95.0%
A19: 40385 | B19: 260 | C19: 260.1 | D19: 257.71001 | E19: 259.28001 | F19: 105137900 | G19: 34.094764 | H19: =(E19-E18)/E18 -> -0.0025390052 | I19: =(G19-G18)/G18 -> -0.0025390012 | J19: 0.0096703351 | L19: Intercept | M19: 0.00044039568 | N19: 0.00036937942 | O19: 1.1922583 | P19: 0.23334743 | Q19: -0.00028415583 | R19: 0.0011649472 | S19: -0.00028415583 | T19: 0.0011649472
A20: 40386 | B20: 260.87 | C20: 264.8 | D20: 260.3 | E20: 264.08001 | F20: 146192900 | G20: 34.725954 | H20: =(E20-E19)/E19 -> 0.018512816 | I20: =(G20-G19)/G19 -> 0.018512813 | J20: 0.0011648684 | L20: DJI | M20: 0.90008643 | N20: 0.040510126 | O20: 22.218801 | P20: 7.4411992e-95 | Q20: 0.8206243 | R20: 0.97954855 | S20: 0.8206243 | T20: 0.97954855
A21: 40387 | B21: 263.66999 | C21: 265.99001 | D21: 260.24999 | E21: 260.95999 | F21: 129996300 | G21: 34.315678 | H21: =(E21-E20)/E20 -> -0.011814669 | I21: =(G21-G20)/G20 -> -0.011814679 | J21: -0.0037779199
A22: 40388 | B22: 260.71 | C22: 262.64999 | D22: 256.09999 | E22: 258.10999 | F22: 160951700 | G22: 33.94091 | H22: =(E22-E21)/E21 -> -0.010921207 | I22: =(G22-G21)/G21 -> -0.010921189 | J22: -0.0029262785
A23: 40389 | B23: 255.89 | C23: 259.69999 | D23: 254.90001 | E23: 257.25 | F23: 112052500 | G23: 33.827822 | H23: =(E23-E22)/E22 -> -0.0033318857 | I23: =(G23-G22)/G22 -> -0.0033319083 | J23: -0.00011652922
A24: 40392 | B24: 260.44001 | C24: 262.58999 | D24: 259.61999 | E24: 261.85 | F24: 107013900 | G24: 34.432712 | H24: =(E24-E23)/E23 -> 0.017881431 | I24: =(G24-G23)/G23 -> 0.017881435 | J24: 0.019915979
A25: 40393 | B25: 261.01001 | C25: 263.25999 | D25: 259.42001 | E25: 261.93 | F25: 104413400 | G25: 34.443232 | H25: =(E25-E24)/E24 -> 0.00030552607 | I25: =(G25-G24)/G24 -> 0.00030552342 | J25: -0.0035599258 | L25: AAPL ALPHA | M25: =M19 -> 0.00044039568
A26: 40394 | B26: 262.84001 | C26: 264.27999 | D26: 260.30999 | E26: 262.98001 | F26: 105093800 | G26: 34.581306 | H26: =(E26-E25)/E25 -> 0.0040087466 | I26: =(G26-G25)/G25 -> 0.0040087411 | J26: 0.0041414288 | L26: AAPLE BETA | M26: =M20 -> 0.90008643
A27: 40395 | B27: 261.73 | C27: 263.17999 | D27: 260.55 | E27: 261.70001 | F27: 72274300 | G27: 34.412989 | H27: =(E27-E26)/E26 -> -0.0048673015 | I27: =(G27-G26)/G26 -> -0.0048672829 | J27: -0.00051020606
A28: 40396 | B28: 259.77999 | C28: 261.48999 | D28: 257.63001 | E28: 260.09001 | F28: 111224400 | G28: 34.201278 | H28: =(E28-E27)/E27 -> -0.0061520671 | I28: =(G28-G27)/G27 -> -0.0061520666 | J28: -0.0020066454
A29: 40399 | B29: 261.48 | C29: 262.15001 | D29: 259.57 | E29: 261.75 | F29: 75782000 | G29: 34.419562 | H29: =(E29-E28)/E28 -> 0.0063823443 | I29: =(G29-G28)/G28 -> 0.0063823346 | J29: 0.0042418151
A30: 40400 | B30: 259.85001 | C30: 260.44999 | D30: 257.55001 | E30: 259.41 | F30: 112980000 | G30: 34.111857 | H30: =(E30-E29)/E29 -> -0.0089398282 | I30: =(G30-G29)/G29 -> -0.008939829 | J30: -0.005094053 | M30: =M25*100 -> 0.044039568
A31: 40401 | B31: 255.4 | C31: 255.68999 | D31: 249.80999 | E31: 250.19 | F31: 155013600 | G31: 32.899447 | H31: =(E31-E30)/E30 -> -0.035542181 | I31: =(G31-G30)/G30 -> -0.035542187 | J31: -0.024935521
A32: 40402 | B32: 246.69 | C32: 253.1 | D32: 246.12 | E32: 251.79001 | F32: 133730100 | G32: 33.109845 | H32: =(E32-E31)/E31 -> 0.0063951797 | I32: =(G32-G31)/G31 -> 0.0063951835 | J32: -0.0056730749
A33: 40403 | B33: 251.65 | C33: 251.88 | D33: 249.09 | E33: 249.09999 | F33: 88717300 | G33: 32.756113 | H33: =(E33-E32)/E32 -> -0.010683593 | I33: =(G33-G32)/G32 -> -0.01068359 | J33: -0.0016278964
A34: 40406 | B34: 247.58001 | C34: 250.01 | D34: 246.62001 | E34: 247.64001 | F34: 79607500 | G34: 32.564129 | H34: =(E34-E33)/E33 -> -0.00586102 | I34: =(G34-G33)/G33 -> -0.0058610129 | J34: -0.00011070594
A35: 40407 | B35: 250.08001 | C35: 254.62999 | D35: 249.19999 | E35: 251.97001 | F35: 105660100 | G35: 33.133515 | H35: =(E35-E34)/E34 -> 0.017485083 | I35: =(G35-G34)/G34 -> 0.017485068 | J35: 0.010079571
A36: 40408 | B36: 252.36001 | C36: 254.66999 | D36: 251.57999 | E36: 253.07001 | F36: 84924000 | G36: 33.278163 | H36: =(E36-E35)/E35 -> 0.0043655909 | I36: =(G36-G35)/G35 -> 0.0043656099 | J36: 0.00093124832
A37: 40409 | B37: 252.83999 | C37: 253.48001 | D37: 248.68 | E37: 249.88001 | F37: 106676500 | G37: 32.858684 | H37: =(E37-E36)/E36 -> -0.012605231 | I37: =(G37-G36)/G36 -> -0.012605233 | J37: -0.013857186
A38: 40410 | B38: 249.39001 | C38: 253.91999 | D38: 249.00001 | E38: 249.64 | F38: 96057500 | G38: 32.827124 | H38: =(E38-E37)/E37 -> -0.00096048501 | I38: =(G38-G37)/G37 -> -0.00096047669 | J38: -0.0056069188
A39: 40413 | B39: 251.79001 | C39: 252 | D39: 245.24999 | E39: 245.79999 | F39: 103510400 | G39: 32.322171 | H39: =(E39-E38)/E38 -> -0.015382178 | I39: =(G39-G38)/G38 -> -0.015382188 | J39: -0.0038389875
A40: 40414 | B40: 242.66999 | C40: 243.00001 | D40: 238.65 | E40: 239.93 | F40: 150641400 | G40: 31.55028 | H40: =(E40-E39)/E39 -> -0.023881156 | I40: =(G40-G39)/G39 -> -0.023881162 | J40: -0.013166361
...

Sheet Bidu
A1: Date | B1: Open | C1: High | D1: Low | E1: Close | F1: Volume | G1: Adj Close | H1: Close Return | I1: Adj Close Return
A2: 40359 | B2: 67.980003 | C2: 70.349998 | D2: 67.68 | E2: 68.080002 | F2: 15191200 | G2: 68.080002 | I2: BDI | J2: DJI
A3: 40360 | B3: 69.349998 | C3: 69.879997 | D3: 65.900002 | E3: 68.550003 | F3: 11540100 | G3: 68.550003 | H3: =(E3-E2)/E2 -> 0.0069036573 | I3: =(G3-G2)/G2 -> 0.0069036573 | J3: -0.0042448511 | L3: SUMMARY OUTPUT
A4: 40361 | B4: 69.379997 | C4: 69.410004 | D4: 67.160004 | E4: 67.550003 | F4: 6293500 | G4: 67.550003 | H4: =(E4-E3)/E3 -> -0.014587891 | I4: =(G4-G3)/G3 -> -0.014587891 | J4: -0.0047315346
A5: 40365 | B5: 69.199997 | C5: 70.059998 | D5: 66.849998 | E5: 67.449997 | F5: 9658200 | G5: 67.449997 | H5: =(E5-E4)/E4 -> -0.0014804737 | I5: =(G5-G4)/G4 -> -0.0014804737 | J5: 0.0058989071 | L5: Regression Statistics
A6: 40366 | B6: 67.519997 | C6: 72.440002 | D6: 67.25 | E6: 72.370003 | F6: 12808300 | G6: 72.370003 | H6: =(E6-E5)/E5 -> 0.072943013 | I6: =(G6-G5)/G5 -> 0.072943013 | J6: 0.028188717 | L6: Multiple R | M6: 0.47933272
A7: 40367 | B7: 73.300003 | C7: 73.75 | D7: 71.099998 | E7: 72.43 | F7: 11403400 | G7: 72.43 | H7: =(E7-E6)/E6 -> 0.00082903133 | I7: =(G7-G6)/G6 -> 0.00082903133 | J7: 0.01204897 | L7: R Square | M7: 0.22975985
A8: 40368 | B8: 70.199997 | C8: 71.839996 | D8: 70.080002 | E8: 71.199997 | F8: 14945000 | G8: 71.199997 | H8: =(E8-E7)/E7 -> -0.016981955 | I8: =(G8-G7)/G7 -> -0.016981955 | J8: 0.005823069 | L8: Adjusted R Square | M8: 0.22924942
A9: 40371 | B9: 70.68 | C9: 71.779999 | D9: 70.349998 | E9: 70.730003 | F9: 8280100 | G9: 70.730003 | H9: =(E9-E8)/E8 -> -0.0066010396 | I9: =(G9-G8)/G8 -> -0.0066010396 | J9: 0.0017885081 | L9: Standard Error | M9: 0.021895822
A10: 40372 | B10: 72.160004 | C10: 74.800003 | D10: 71.389999 | E10: 74.379997 | F10: 13455900 | G10: 74.379997 | H10: =(E10-E9)/E9 -> 0.051604607 | I10: =(G10-G9)/G9 -> 0.051604607 | J10: 0.014364343 | L10: Observations | M10: 1511
A11: 40373 | B11: 75.139999 | C11: 75.480003 | D11: 73.989998 | E11: 75.029999 | F11: 9501900 | G11: 75.029999 | H11: =(E11-E10)/E10 -> 0.0087389356 | I11: =(G11-G10)/G10 -> 0.0087389356 | J11: 0.00035705809
A12: 40374 | B12: 75.010002 | C12: 75.860001 | D12: 74.110001 | E12: 75.639999 | F12: 8528600 | G12: 75.639999 | H12: =(E12-E11)/E11 -> 0.0081300814 | I12: =(G12-G11)/G11 -> 0.0081300814 | J12: -0.00071480277 | L12: ANOVA
A13: 40375 | B13: 75.230003 | C13: 75.699997 | D13: 73.290001 | E13: 73.529999 | F13: 10384900 | G13: 73.529999 | H13: =(E13-E12)/E12 -> -0.027895294 | I13: =(G13-G12)/G12 -> -0.027895294 | J13: -0.025234228 | M13: df | N13: SS | O13: MS | P13: F | Q13: Significance F
A14: 40378 | B14: 71.669998 | C14: 73.389999 | D14: 70.379997 | E14: 72.900002 | F14: 15400600 | G14: 72.900002 | H14: =(E14-E13)/E13 -> -0.0085678908 | I14: =(G14-G13)/G13 -> -0.0085678908 | J14: 0.0055981241 | L14: Regression | M14: 1 | N14: 0.21580412 | O14: 0.21580412 | P14: 450.12925 | Q14: 1.2312866e-87
A15: 40379 | B15: 71.260002 | C15: 74.230003 | D15: 70.75 | E15: 74.040001 | F15: 9721000 | G15: 74.040001 | H15: =(E15-E14)/E14 -> 0.015637846 | I15: =(G15-G14)/G14 -> 0.015637846 | J15: 0.0074381597 | L15: Residual | M15: 1509 | N15: 0.72345537 | O15: 0.00047942702
A16: 40380 | B16: 74.980003 | C16: 76.580002 | D16: 73 | E16: 73.309998 | F16: 18796800 | G16: 73.309998 | H16: =(E16-E15)/E15 -> -0.0098595758 | I16: =(G16-G15)/G15 -> -0.0098595758 | J16: -0.010696981 | L16: Total | M16: 1510 | N16: 0.9392595
A17: 40381 | B17: 76.379997 | C17: 76.459999 | D17: 72.300003 | E17: 74.449997 | F17: 19747500 | G17: 74.449997 | H17: =(E17-E16)/E16 -> 0.015550389 | I17: =(G17-G16)/G16 -> 0.015550389 | J17: 0.019936657
A18: 40382 | B18: 75.400002 | C18: 78.220001 | D18: 74.5 | E18: 78.059998 | F18: 13308300 | G18: 78.059998 | H18: =(E18-E17)/E17 -> 0.048488934 | I18: =(G18-G17)/G17 -> 0.048488934 | J18: 0.0099125497 | M18: Coefficients | N18: Standard Error | O18: t Stat | P18: P-value | Q18: Lower 95% | R18: Upper 95% | S18: Lower 95.0% | T18: Upper 95.0%
A19: 40385 | B19: 78.870003 | C19: 80.870003 | D19: 78.300003 | E19: 80.370003 | F19: 13939300 | G19: 80.370003 | H19: =(E19-E18)/E18 -> 0.029592686 | I19: =(G19-G18)/G18 -> 0.029592686 | J19: 0.0096703351 | L19: Intercept | M19: 0.00031565585 | N19: 0.00056395259 | O19: 0.55972053 | P19: 0.57575314 | Q19: -0.0007905582 | R19: 0.0014218699 | S19: -0.0007905582 | T19: 0.0014218699
A20: 40386 | B20: 80.730003 | C20: 81.989998 | D20: 80.110001 | E20: 81.07 | F20: 10737400 | G20: 81.07 | H20: =(E20-E19)/E19 -> 0.0087096799 | I20: =(G20-G19)/G19 -> 0.0087096799 | J20: 0.0011648684 | L20: DJI | M20: 1.3122063 | N20: 0.061849116 | O20: 21.21625 | P20: 1.2312866e-87 | Q20: 1.1908869 | R20: 1.4335256 | S20: 1.1908869 | T20: 1.4335256
A21: 40387 | B21: 80.779999 | C21: 81.18 | D21: 78.879997 | E21: 79.400002 | F21: 7746700 | G21: 79.400002 | H21: =(E21-E20)/E20 -> -0.020599457 | I21: =(G21-G20)/G20 -> -0.020599457 | J21: -0.0037779199
A22: 40388 | B22: 80.089996 | C22: 80.459999 | D22: 77.639999 | E22: 79.199997 | F22: 9387900 | G22: 79.199997 | H22: =(E22-E21)/E21 -> -0.0025189546 | I22: =(G22-G21)/G21 -> -0.0025189546 | J22: -0.0029262785
A23: 40389 | B23: 79.400002 | C23: 81.550003 | D23: 78.300003 | E23: 81.410004 | F23: 12327800 | G23: 81.410004 | H23: =(E23-E22)/E22 -> 0.02790413 | I23: =(G23-G22)/G22 -> 0.02790413 | J23: -0.00011652922
A24: 40392 | B24: 83.029999 | C24: 84.980003 | D24: 82.900002 | E24: 84.599998 | F24: 13600000 | G24: 84.599998 | H24: =(E24-E23)/E23 -> 0.0391843 | I24: =(G24-G23)/G23 -> 0.0391843 | J24: 0.019915979 | L24: BIDU ALPHA | M24: =M19 -> 0.00031565585
A25: 40393 | B25: 84.620003 | C25: 85.349998 | D25: 82.800003 | E25: 84.790001 | F25: 10146900 | G25: 84.790001 | H25: =(E25-E24)/E24 -> 0.0022458984 | I25: =(G25-G24)/G24 -> 0.0022458984 | J25: -0.0035599258 | L25: BIDU BETA | M25: =M20 -> 1.3122063
A26: 40394 | B26: 85.410004 | C26: 86.910004 | D26: 85.07 | E26: 86.599998 | F26: 11704500 | G26: 86.599998 | H26: =(E26-E25)/E25 -> 0.021346821 | I26: =(G26-G25)/G25 -> 0.021346821 | J26: 0.0041414288
A27: 40395 | B27: 86.260002 | C27: 86.459999 | D27: 84.849998 | E27: 85.57 | F27: 8026600 | G27: 85.57 | H27: =(E27-E26)/E26 -> -0.011893742 | I27: =(G27-G26)/G26 -> -0.011893742 | J27: -0.00051020606
A28: 40396 | B28: 84.639999 | C28: 86.599998 | D28: 84.330002 | E28: 86.529999 | F28: 8692300 | G28: 86.529999 | H28: =(E28-E27)/E27 -> 0.011218873 | I28: =(G28-G27)/G27 -> 0.011218873 | J28: -0.0020066454
A29: 40399 | B29: 87.449997 | C29: 88 | D29: 86.699997 | E29: 87.559998 | F29: 8792800 | G29: 87.559998 | H29: =(E29-E28)/E28 -> 0.011903375 | I29: =(G29-G28)/G28 -> 0.011903375 | J29: 0.0042418151
A30: 40400 | B30: 86.510002 | C30: 88.32 | D30: 85.620003 | E30: 87.870003 | F30: 9241200 | G30: 87.870003 | H30: =(E30-E29)/E29 -> 0.0035404866 | I30: =(G30-G29)/G29 -> 0.0035404866 | J30: -0.005094053
A31: 40401 | B31: 85.75 | C31: 86.349998 | D31: 83.440002 | E31: 84.230003 | F31: 11797200 | G31: 84.230003 | H31: =(E31-E30)/E30 -> -0.041424831 | I31: =(G31-G30)/G30 -> -0.041424831 | J31: -0.024935521
A32: 40402 | B32: 81.849998 | C32: 84.110001 | D32: 80.099998 | E32: 82.650002 | F32: 12296600 | G32: 82.650002 | H32: =(E32-E31)/E31 -> -0.018758173 | I32: =(G32-G31)/G31 -> -0.018758173 | J32: -0.0056730749
A33: 40403 | B33: 82.760002 | C33: 83.5 | D33: 82.040001 | E33: 82.830002 | F33: 6509900 | G33: 82.830002 | H33: =(E33-E32)/E32 -> 0.0021778584 | I33: =(G33-G32)/G32 -> 0.0021778584 | J33: -0.0016278964
A34: 40406 | B34: 82.309998 | C34: 85.269997 | D34: 82.110001 | E34: 84.349998 | F34: 7411800 | G34: 84.349998 | H34: =(E34-E33)/E33 -> 0.01835079 | I34: =(G34-G33)/G33 -> 0.01835079 | J34: -0.00011070594
A35: 40407 | B35: 85.769997 | C35: 86.050003 | D35: 84.300003 | E35: 84.43 | F35: 7173200 | G35: 84.43 | H35: =(E35-E34)/E34 -> 0.0009484529 | I35: =(G35-G34)/G34 -> 0.0009484529 | J35: 0.010079571
A36: 40408 | B36: 84.660004 | C36: 84.800003 | D36: 82.800003 | E36: 82.919998 | F36: 7654500 | G36: 82.919998 | H36: =(E36-E35)/E35 -> -0.017884662 | I36: =(G36-G35)/G35 -> -0.017884662 | J36: 0.00093124832
A37: 40409 | B37: 82.550003 | C37: 83.300003 | D37: 81.010002 | E37: 81.190002 | F37: 8077800 | G37: 81.190002 | H37: =(E37-E36)/E36 -> -0.020863435 | I37: =(G37-G36)/G36 -> -0.020863435 | J37: -0.013857186
... A1513: 42551 | B1513: 165.07001 | C1513: 165.26 | D1513: 162.10001 | E1513: 165.14999 | F1513: 1809300 | G1513: 165.14999 | H1513: =(E1513-E1512)/E1512 -> 0.0045008818 | I1513: =(G1513-G1512)/G1512 -> 0.0045008818 | J1513: 0.013298378
H1514: =MIN(I3:I1513) -> -0.14998986 | I1514: =AVERAGE(I3:I1513) -> 0.00089719644
G1515: =(I1514-0)/I1515 -> 0.035985453 | H1515: =MAX(I3:I1513) -> 0.11008199 | I1515: =STDEVP(I3:I1513) -> 0.024932198

Sheet Msft
A1: Date | B1: Open | C1: High | D1: Low | E1: Close | F1: Volume | G1: Adj Close | I1: Adj Close Return
A2: 40359 | B2: 23.299999 | C2: 23.68 | D2: 22.950001 | E2: 23.01 | F2: 81050500 | G2: 19.541996 | I2: MSFT | J2: DJI
A3: 40360 | B3: 23.09 | C3: 23.32 | D3: 22.73 | E3: 23.16 | F3: 92239400 | G3: 19.669388 | H3: =(E3-E2)/E2 -> 0.0065189048 | I3: =(G3-G2)/G2 -> 0.0065188837 | J3: -0.0042448511 | L3: SUMMARY OUTPUT
A4: 40361 | B4: 23.360001 | C4: 23.48 | D4: 23.049999 | E4: 23.27 | F4: 62485100 | G4: 19.76281 | H4: =(E4-E3)/E3 -> 0.0047495682 | I4: =(G4-G3)/G3 -> 0.004749614 | J4: -0.0047315346
A5: 40365 | B5: 23.700001 | C5: 24.09 | D5: 23.58 | E5: 23.82 | F5: 73592000 | G5: 20.229915 | H5: =(E5-E4)/E4 -> 0.023635582 | I5: =(G5-G4)/G4 -> 0.023635556 | J5: 0.0058989071 | L5: Regression Statistics
A6: 40366 | B6: 23.82 | C6: 24.32 | D6: 23.610001 | E6: 24.299999 | F6: 79965300 | G6: 20.63757 | H6: =(E6-E5)/E5 -> 0.020151092 | I6: =(G6-G5)/G5 -> 0.020151098 | J6: 0.028188717 | L6: Multiple R | M6: 0.64156449
A7: 40367 | B7: 24.6 | C7: 24.620001 | D7: 23.969999 | E7: 24.41 | F7: 50758100 | G7: 20.730992 | H7: =(E7-E6)/E6 -> 0.0045267903 | I7: =(G7-G6)/G6 -> 0.0045267926 | J7: 0.01204897 | L7: R Square | M7: 0.41160499
A8: 40368 | B8: 24.33 | C8: 24.41 | D8: 24.15 | E8: 24.27 | F8: 53806100 | G8: 20.612093 | H8: =(E8-E7)/E7 -> -0.0057353544 | I8: =(G8-G7)/G7 -> -0.0057353261 | J8: 0.005823069 | L8: Adjusted R Square | M8: 0.41121507
A9: 40371 | B9: 24.43 | C9: 24.889999 | D9: 24.42 | E9: 24.83 | F9: 49854200 | G9: 21.08769 | H9: =(E9-E8)/E8 -> 0.023073754 | I9: =(G9-G8)/G8 -> 0.023073688 | J9: 0.0017885081 | L9: Standard Error | M9: 0.011370131
A10: 40372 | B10: 25.139999 | C10: 25.299999 | D10: 24.9 | E10: 25.129999 | F10: 61928700 | G10: 21.342475 | H10: =(E10-E9)/E9 -> 0.012082118 | I10: =(G10-G9)/G9 -> 0.012082167 | J10: 0.014364343 | L10: Observations | M10: 1511
A11: 40373 | B11: 25.5 | C11: 25.610001 | D11: 25.120001 | E11: 25.440001 | F11: 72808100 | G11: 21.605753 | H11: =(E11-E10)/E10 -> 0.012335934 | I11: =(G11-G10)/G10 -> 0.01233587 | J11: 0.00035705809
A12: 40374 | B12: 25.5 | C12: 25.59 | D12: 24.98 | E12: 25.51 | F12: 56934700 | G12: 21.665203 | H12: =(E12-E11)/E11 -> 0.0027515329 | I12: =(G12-G11)/G11 -> 0.002751582 | J12: -0.00071480277 | L12: ANOVA
A13: 40375 | B13: 25.51 | C13: 25.639999 | D13: 24.879999 | E13: 24.889999 | F13: 65064800 | G13: 21.138647 | H13: =(E13-E12)/E12 -> -0.024304234 | I13: =(G13-G12)/G12 -> -0.024304226 | J13: -0.025234228 | M13: df | N13: SS | O13: MS | P13: F | Q13: Significance F
A14: 40378 | B14: 24.959999 | C14: 25.299999 | D14: 24.91 | E14: 25.23 | F14: 38181800 | G14: 21.427403 | H14: =(E14-E13)/E13 -> 0.013660145 | I14: =(G14-G13)/G13 -> 0.013660098 | J14: 0.0055981241 | L14: Regression | M14: 1 | N14: 0.13646832 | O14: 0.13646832 | P14: 1055.6037 | Q14: 5.2494976e-176
A15: 40379 | B15: 24.860001 | C15: 25.48 | D15: 24.700001 | E15: 25.48 | F15: 45530700 | G15: 21.639724 | H15: =(E15-E14)/E14 -> 0.0099088387 | I15: =(G15-G14)/G14 -> 0.0099088536 | J15: 0.0074381597 | L15: Residual | M15: 1509 | N15: 0.19508335 | O15: 0.00012927989
A16: 40380 | B16: 25.6 | C16: 25.65 | D16: 24.98 | E16: 25.120001 | F16: 73297300 | G16: 21.333983 | H16: =(E16-E15)/E15 -> -0.014128689 | I16: =(G16-G15)/G15 -> -0.014128692 | J16: -0.010696981 | L16: Total | M16: 1510 | N16: 0.33155167
A17: 40381 | B17: 25.51 | C17: 25.99 | D17: 25.469999 | E17: 25.84 | F17: 73016400 | G17: 21.945466 | H17: =(E17-E16)/E16 -> 0.028662379 | I17: =(G17-G16)/G16 -> 0.028662393 | J17: 0.019936657
A18: 40382 | B18: 25.84 | C18: 26.02 | D18: 25.25 | E18: 25.809999 | F18: 108520100 | G18: 21.919987 | H18: =(E18-E17)/E17 -> -0.0011610294 | I18: =(G18-G17)/G17 -> -0.0011610143 | J18: 0.0099125497 | M18: Coefficients | N18: Standard Error | O18: t Stat | P18: P-value | Q18: Lower 95% | R18: Upper 95% | S18: Lower 95.0% | T18: Upper 95.0%
A19: 40385 | B19: 25.860001 | C19: 26.200001 | D19: 25.799999 | E19: 26.1 | F19: 67249900 | G19: 22.16628 | H19: =(E19-E18)/E18 -> 0.011235994 | I19: =(G19-G18)/G18 -> 0.011236001 | J19: 0.0096703351 | L19: Intercept | M19: 0.00028448409 | N19: 0.00029285108 | O19: 0.97142921 | P19: 0.33149027 | Q19: -0.00028995422 | R19: 0.00085892241 | S19: -0.00028995422 | T19: 0.00085892241
A20: 40386 | B20: 26.139999 | C20: 26.24 | D20: 25.959999 | E20: 26.16 | F20: 60672100 | G20: 22.217236 | H20: =(E20-E19)/E19 -> 0.0022988506 | I20: =(G20-G19)/G19 -> 0.002298807 | J20: 0.0011648684 | L20: DJI | M20: 1.0434897 | N20: 0.032117204 | O20: 32.490055 | P20: 5.2494976e-176 | Q20: 0.98049063 | R20: 1.1064888 | S20: 0.98049063 | T20: 1.1064888
A21: 40387 | B21: 26.07 | C21: 26.190001 | D21: 25.83 | E21: 25.950001 | F21: 69704800 | G21: 22.038888 | H21: =(E21-E20)/E20 -> -0.0080274847 | I21: =(G21-G20)/G20 -> -0.0080274612 | J21: -0.0037779199
A22: 40388 | B22: 26.129999 | C22: 26.41 | D22: 25.6 | E22: 26.030001 | F22: 69446200 | G22: 22.10683 | H22: =(E22-E21)/E21 -> 0.0030828515 | I22: =(G22-G21)/G21 -> 0.0030828234 | J22: -0.0029262785
A23: 40389 | B23: 25.75 | C23: 25.84 | D23: 25.35 | E23: 25.809999 | F23: 83534800 | G23: 21.919987 | H23: =(E23-E22)/E22 -> -0.0084518629 | I23: =(G23-G22)/G22 -> -0.0084518224 | J23: -0.00011652922
A24: 40392 | B24: 25.99 | C24: 26.379999 | D24: 25.75 | E24: 26.33 | F24: 55044600 | G24: 22.361615 | H24: =(E24-E23)/E23 -> 0.020147269 | I24: =(G24-G23)/G23 -> 0.020147275 | J24: 0.019915979
A25: 40393 | B25: 26.200001 | C25: 26.35 | D25: 25.969999 | E25: 26.16 | F25: 56877700 | G25: 22.217236 | H25: =(E25-E24)/E24 -> -0.0064565135 | I25: =(G25-G24)/G24 -> -0.0064565551 | J25: -0.0035599258
A26: 40394 | B26: 26.15 | C26: 26.24 | D26: 25.440001 | E26: 25.73 | F26: 78531900 | G26: 21.852045 | H26: =(E26-E25)/E25 -> -0.016437309 | I26: =(G26-G25)/G25 -> -0.016437283 | J26: 0.0041414288 | L26: MSFT ALPHA | M26: =M19 -> 0.00028448409
A27: 40395 | B27: 25.49 | C27: 25.58 | D27: 25.209999 | E27: 25.370001 | F27: 64922100 | G27: 21.546304 | H27: =(E27-E26)/E26 -> -0.013991411 | I27: =(G27-G26)/G26 -> -0.013991414 | J27: -0.00051020606 | L27: MSFT BETA | M27: =M20 -> 1.0434897
A28: 40396 | B28: 25.18 | C28: 25.559999 | D28: 25.02 | E28: 25.549999 | F28: 55982100 | G28: 21.699173 | H28: =(E28-E27)/E27 -> 0.007094915 | I28: =(G28-G27)/G27 -> 0.0070949059 | J28: -0.0020066454
A29: 40399 | B29: 25.549999 | C29: 25.73 | D29: 25.370001 | E29: 25.610001 | F29: 57096500 | G29: 21.750132 | H29: =(E29-E28)/E28 -> 0.002348415 | I29: =(G29-G28)/G28 -> 0.0023484305 | J29: 0.0042418151
A30: 40400 | B30: 25.33 | C30: 25.34 | D30: 24.879999 | E30: 25.07 | F30: 87257700 | G30: 21.291518 | H30: =(E30-E29)/E29 -> -0.021085552 | I30: =(G30-G29)/G29 -> -0.021085573 | J30: -0.005094053
A31: 40401 | B31: 24.68 | C31: 24.9 | D31: 24.559999 | E31: 24.860001 | F31: 76746900 | G31: 21.113169 | H31: =(E31-E30)/E30 -> -0.0083765058 | I31: =(G31-G30)/G30 -> -0.0083765282 | J31: -0.024935521
A32: 40402 | B32: 24.42 | C32: 24.68 | D32: 24.360001 | E32: 24.49 | F32: 70240500 | G32: 20.798934 | H32: =(E32-E31)/E31 -> -0.014883386 | I32: =(G32-G31)/G31 -> -0.014883365 | J32: -0.0056730749
A33: 40403 | B33: 24.35 | C33: 24.67 | D33: 24.24 | E33: 24.4 | F33: 45263500 | G33: 20.722499 | H33: =(E33-E32)/E32 -> -0.0036749694 | I33: =(G33-G32)/G32 -> -0.003674948 | J33: -0.0016278964
A34: 40406 | B34: 24.360001 | C34: 24.610001 | D34: 24.299999 | E34: 24.5 | F34: 40909700 | G34: 20.807427 | H34: =(E34-E33)/E33 -> 0.0040983607 | I34: =(G34-G33)/G33 -> 0.0040983474 | J34: -0.00011070594
A35: 40407 | B35: 24.709999 | C35: 24.959999 | D35: 24.6 | E35: 24.709999 | F35: 52912600 | G35: 21.097723 | H35: =(E35-E34)/E34 -> 0.0085713878 | I35: =(G35-G34)/G34 -> 0.013951557 | J35: 0.010079571
A36: 40408 | B36: 24.68 | C36: 24.950001 | D36: 24.41 | E36: 24.82 | F36: 46818900 | G36: 21.191643 | H36: =(E36-E35)/E35 -> 0.0044516797 | I36: =(G36-G35)/G35 -> 0.0044516652 | J36: 0.00093124832
A37: 40409 | B37: 24.620001 | C37: 24.74 | D37: 24.209999 | E37: 24.440001 | F37: 54064600 | G37: 20.867194 | H37: =(E37-E36)/E36 -> -0.015310193 | I37: =(G37-G36)/G36 -> -0.015310233 | J37: -0.013857186
A38: 40410 | B38: 24.309999 | C38: 24.4 | D38: 24.200001 | E38: 24.23 | F38: 49560100 | G38: 20.687893 | H38: =(E38-E37)/E37 -> -0.0085925119 | I38: =(G38-G37)/G37 -> -0.0085924825 | J38: -0.0056069188
A39: 40413 | B39: 24.440001 | C39: 24.639999 | D39: 24.24 | E39: 24.280001 | F39: 51643000 | G39: 20.730584 | H39: =(E39-E38)/E38 -> 0.0020635988 | I39: =(G39-G38)/G38 -> 0.0020635741 | J39: -0.0038389875
... A1513: 42551 | B1513: 50.720001 | C1513: 51.299999 | D1513: 50.5 | E1513: 51.169998 | F1513: 28527800 | G1513: 51.169998 | H1513: =(E1513-E1512)/E1512 -> 0.012465314 | I1513: =(G1513-G1512)/G1512 -> 0.012465314 | J1513: 0.013298378
...

Sheet __OpenSolverCache__

Sheet __OpenSolver__
A1: =ModelSheet='Portfolio 1'!A:Z -> #NAME?
A2: =OpenSolver_AdjNum=1 -> #NAME?
A3: =OpenSolver_ChosenSolver=SolveEngine -> #NAME?
A4: =OpenSolver_FastBuild=0 -> #NAME?
A5: =OpenSolver_LinearityCheck=1 -> #NAME?
A6: =solver_adj='Portfolio 1'!G33:H33 -> #NAME?
A7: =solver_lhs1='Portfolio 1'!G33 -> #NAME?
A8: =solver_lhs2='Portfolio 1'!G33 -> #NAME?
A9: =solver_neg=1 -> #NAME?
A10: =solver_num=2 -> #NAME?
A11: =solver_opt='Portfolio 1'!G34 -> #NAME?
A12: =solver_rel1=1 -> #NAME?
A13: =solver_rel2=3 -> #NAME?
A14: =solver_rhs1='Portfolio 1'!J33 -> #NAME?
A15: =solver_rhs2='Portfolio 1'!J34 -> #NAME?
A16: =solver_sho=1 -> #NAME?
A17: =solver_typ=2 -> #NAME?
A18: =solver_val=0 -> #NAME?

Sheet Dji
A1: Date | B1: Open | C1: High | D1: Low | E1: Close | F1: Volume | G1: Adj Close
A2: 40359 | B2: 9868.3398 | C2: 9908.9199 | D2: 9753.8398 | E2: 9774.0195 | F2: 235090000 | G2: 9774.0195
A3: 40360 | B3: 9773.2695 | C3: 9795.4805 | D3: 9621.8896 | E3: 9732.5303 | F3: 262820000 | G3: 9732.5303 | H3: =(E3-E2)/E2 -> -0.0042448511 | I3: =(G3-G2)/G2 -> -0.0042448511
A4: 40361 | B4: 9732.5303 | C4: 9770.8701 | D4: 9614.3203 | E4: 9686.4805 | F4: 199570000 | G4: 9686.4805 | H4: =(E4-E3)/E3 -> -0.0047315346 | I4: =(G4-G3)/G3 -> -0.0047315346
A5: 40365 | B5: 9686.4805 | C5: 9858.1299 | D5: 9659.0098 | E5: 9743.6201 | F5: 261020000 | G5: 9743.6201 | H5: =(E5-E4)/E4 -> 0.0058989071 | I5: =(G5-G4)/G4 -> 0.0058989071
A6: 40366 | B6: 9743.6201 | C6: 10026.6 | D6: 9736.7002 | E6: 10018.28 | F6: 219560000 | G6: 10018.28 | H6: =(E6-E5)/E5 -> 0.028188717 | I6: =(G6-G5)/G5 -> 0.028188717
A7: 40367 | B7: 10019.26 | C7: 10139.86 | D7: 10019.26 | E7: 10138.99 | F7: 192210000 | G7: 10138.99 | H7: =(E7-E6)/E6 -> 0.01204897 | I7: =(G7-G6)/G6 -> 0.01204897
A8: 40368 | B8: 10138.99 | C8: 10201.77 | D8: 10118.41 | E8: 10198.03 | F8: 134810000 | G8: 10198.03 | H8: =(E8-E7)/E7 -> 0.005823069 | I8: =(G8-G7)/G7 -> 0.005823069
A9: 40371 | B9: 10199.24 | C9: 10220.28 | D9: 10146.49 | E9: 10216.27 | F9: 131490000 | G9: 10216.27 | H9: =(E9-E8)/E8 -> 0.0017885081 | I9: =(G9-G8)/G8 -> 0.0017885081
A10: 40372 | B10: 10217.55 | C10: 10407.82 | D10: 10217.55 | E10: 10363.02 | F10: 179040000 | G10: 10363.02 | H10: =(E10-E9)/E9 -> 0.014364343 | I10: =(G10-G9)/G9 -> 0.014364343
A11: 40373 | B11: 10370.96 | C11: 10400.1 | D11: 10303 | E11: 10366.72 | F11: 208530000 | G11: 10366.72 | H11: =(E11-E10)/E10 -> 0.00035705809 | I11: =(G11-G10)/G10 -> 0.00035705809
A12: 40374 | B12: 10367.1 | C12: 10379.74 | D12: 10240.48 | E12: 10359.31 | F12: 210000000 | G12: 10359.31 | H12: =(E12-E11)/E11 -> -0.00071480277 | I12: =(G12-G11)/G11 -> -0.00071480277
A13: 40375 | B13: 10356.2 | C13: 10356.2 | D13: 10079.58 | E13: 10097.9 | F13: 335060000 | G13: 10097.9 | H13: =(E13-E12)/E12 -> -0.025234228 | I13: =(G13-G12)/G12 -> -0.025234228
A14: 40378 | B14: 10098.12 | C14: 10187.28 | D14: 10073.68 | E14: 10154.43 | F14: 176970000 | G14: 10154.43 | H14: =(E14-E13)/E13 -> 0.0055981241 | I14: =(G14-G13)/G13 -> 0.0055981241
... A1513: 42551 | B1513: 17712.76 | C1513: 17930.609 | D1513: 17711.801 | E1513: 17929.99 | F1513: 133030000 | G1513: 17929.99 | H1513: =(E1513-E1512)/E1512 -> 0.013298378 | I1513: =(G1513-G1512)/G1512 -> 0.013298378
G1514: =MIN(I3:I1513) -> -0.055463727 | H1514: Average= | I1514: =AVERAGE(I3:I1513) -> 0.00044317772
C1515: =I1514 -> 0.00044317772 | D1515: =I1515 -> 0.0091074233 | F1515: =(C1515-0)/D1515 -> 0.048661153 | G1515: =MAX((I3:I1513)) -> 0.042407884 | H1515: std= | I1515: =STDEVP(I3:I1513) -> 0.0091074233

Sheet Cop
A1: Date | B1: Open | C1: High | D1: Low | E1: Close | F1: Volume | G1: Adj Close
A2: 40359 | B2: 49.719965 | C2: 50.28996 | D2: 48.969958 | E2: 49.089961 | F2: 19329600 | G2: 29.174816 | I2: COP | J2: DJI
A3: 40360 | B3: 49.239964 | C3: 49.569958 | D3: 48.059956 | E3: 48.869962 | F3: 18899300 | G3: 29.044067 | H3: =(E3-E2)/E2 -> -0.0044815477 | I3: =(G3-G2)/G2 -> -0.0044815707 | J3: -0.0042448511 | L3: SUMMARY OUTPUT
A4: 40361 | B4: 49.169967 | C4: 49.359967 | D4: 48.409957 | E4: 48.819956 | F4: 9494200 | G4: 29.014348 | H4: =(E4-E3)/E3 -> -0.0010232461 | I4: =(G4-G3)/G3 -> -0.0010232382 | J4: -0.0047315346
A5: 40365 | B5: 49.969964 | C5: 50.249967 | D5: 48.609965 | E5: 49.199956 | F5: 20722400 | G5: 29.240187 | H5: =(E5-E4)/E4 -> 0.0077837022 | I5: =(G5-G4)/G4 -> 0.0077837007 | J5: 0.0058989071 | L5: Regression Statistics
A6: 40366 | B6: 49.269968 | C6: 51.259966 | D6: 49.269968 | E6: 51.159965 | F6: 15830600 | G6: 30.405046 | H6: =(E6-E5)/E5 -> 0.039837617 | I6: =(G6-G5)/G5 -> 0.039837604 | J6: 0.028188717 | L6: Multiple R | M6: 0.63510364
A7: 40367 | B7: 52.159955 | C7: 52.169954 | D7: 50.959957 | E7: 51.549963 | F7: 11443900 | G7: 30.636827 | H7: =(E7-E6)/E6 -> 0.0076231092 | I7: =(G7-G6)/G6 -> 0.0076231097 | J7: 0.01204897 | L7: R Square | M7: 0.40335663
A8: 40368 | B8: 51.649959 | C8: 52.469958 | D8: 51.39996 | E8: 52.299965 | F8: 11313200 | G8: 31.082563 | H8: =(E8-E7)/E7 -> 0.014549031 | I8: =(G8-G7)/G7 -> 0.014549026 | J8: 0.005823069 | L8: Adjusted R Square | M8: 0.40296124
A9: 40371 | B9: 52.039958 | C9: 52.639957 | D9: 51.77996 | E9: 52.099956 | F9: 12374900 | G9: 30.963696 | H9: =(E9-E8)/E8 -> -0.0038242664 | I9: =(G9-G8)/G8 -> -0.0038242342 | J9: 0.0017885081 | L9: Standard Error | M9: 0.0129527
A10: 40372 | B10: 52.889956 | C10: 53.649956 | D10: 52.689958 | E10: 53.219965 | F10: 11283200 | G10: 31.629332 | H10: =(E10-E9)/E9 -> 0.021497312 | I10: =(G10-G9)/G9 -> 0.021497304 | J10: 0.014364343 | L10: Observations | M10: 1511
A11: 40373 | B11: 53.089964 | C11: 53.459956 | D11: 52.469958 | E11: 52.799952 | F11: 10444800 | G11: 31.379713 | H11: =(E11-E10)/E10 -> -0.0078920195 | I11: =(G11-G10)/G10 -> -0.0078920099 | J11: 0.00035705809
A12: 40374 | B12: 52.739963 | C12: 53.029965 | D12: 52.059959 | E12: 52.859956 | F12: 9567500 | G12: 31.415374 | H12: =(E12-E11)/E11 -> 0.0011364404 | I12: =(G12-G11)/G11 -> 0.0011364349 | J12: -0.00071480277 | L12: ANOVA
A13: 40375 | B13: 52.599959 | C13: 52.799952 | D13: 51.599954 | E13: 51.849958 | F13: 11406400 | G13: 30.815118 | H13: =(E13-E12)/E12 -> -0.019107053 | I13: =(G13-G12)/G12 -> -0.019107078 | J13: -0.025234228 | M13: df | N13: SS | O13: MS | P13: F | Q13: Significance F
A14: 40378 | B14: 52.199953 | C14: 52.279958 | D14: 51.489959 | E14: 51.839959 | F14: 9327000 | G14: 30.809176 | H14: =(E14-E13)/E13 -> -0.0001928449 | I14: =(G14-G13)/G13 -> -0.00019282743 | J14: 0.0055981241 | L14: Regression | M14: 1 | N14: 0.17115288 | O14: 0.17115288 | P14: 1020.149 | Q14: 1.9323394e-171
A15: 40379 | B15: 50.999954 | C15: 52.859956 | D15: 50.799961 | E15: 52.659958 | F15: 12506700 | G15: 31.296512 | H15: =(E15-E14)/E14 -> 0.015817894 | I15: =(G15-G14)/G14 -> 0.015817885 | J15: 0.0074381597 | L15: Residual | M15: 1509 | N15: 0.2531686 | O15: 0.00016777243
A16: 40380 | B16: 53.079956 | C16: 53.129962 | D16: 51.649959 | E16: 52.119963 | F16: 11407400 | G16: 30.975586 | H16: =(E16-E15)/E15 -> -0.010254376 | I16: =(G16-G15)/G15 -> -0.01025437 | J16: -0.010696981 | L16: Total | M16: 1510 | N16: 0.42432148
A17: 40381 | B17: 52.789959 | C17: 53.889961 | D17: 52.56996 | E17: 53.269956 | F17: 11721700 | G17: 31.659042 | H17: =(E17-E16)/E16 -> 0.022064348 | I17: =(G17-G16)/G16 -> 0.022064344 | J17: 0.019936657
A18: 40382 | B18: 53.229958 | C18: 53.859957 | D18: 52.759955 | E18: 53.78996 | F18: 10457800 | G18: 31.968087 | H18: =(E18-E17)/E17 -> 0.009761675 | I18: =(G18-G17)/G17 -> 0.0097616662 | J18: 0.0099125497 | M18: Coefficients | N18: Standard Error | O18: t Stat | P18: P-value | Q18: Lower 95% | R18: Upper 95% | S18: Lower 95.0% | T18: Upper 95.0%
A19: 40385 | B19: 53.989958 | C19: 54.70996 | D19: 53.769959 | E19: 54.429957 | F19: 8437900 | G19: 32.348446 | H19: =(E19-E18)/E18 -> 0.011898075 | I19: =(G19-G18)/G18 -> 0.011898084 | J19: 0.0096703351 | L19: Intercept | M19: -0.00011507642 | N19: 0.00033361198 | O19: -0.34494091 | P19: 0.73018686 | Q19: -0.00076946877 | R19: 0.00053931593 | S19: -0.00076946877 | T19: 0.00053931593
A20: 40386 | B20: 54.729962 | C20: 54.949951 | D20: 54.119954 | E20: 54.439955 | F20: 10823000 | G20: 32.354388 | H20: =(E20-E19)/E19 -> 0.00018368561 | I20: =(G20-G19)/G19 -> 0.00018368734 | J20: 0.0011648684 | L20: DJI | M20: 1.1685959 | N20: 0.036587484 | O20: 31.939772 | P20: 1.9323394e-171 | Q20: 1.0968282 | R20: 1.2403636 | S20: 1.0968282 | T20: 1.2403636
A21: 40387 | B21: 55.019963 | C21: 55.19995 | D21: 53.809951 | E21: 54.439955 | F21: 14859400 | G21: 32.354388 | H21: =(E21-E20)/E20 -> 0 | I21: =(G21-G20)/G20 -> 0 | J21: -0.0037779199
A22: 40388 | B22: 54.679961 | C22: 55.549951 | D22: 54.119954 | E22: 54.559958 | F22: 14933200 | G22: 32.756641 | H22: =(E22-E21)/E21 -> 0.0022043185 | I22: =(G22-G21)/G21 -> 0.012432719 | J22: -0.0029262785
A23: 40389 | B23: 54.099963 | C23: 55.76995 | D23: 53.889961 | E23: 55.219956 | F23: 15913200 | G23: 33.15289 | H23: =(E23-E22)/E22 -> 0.012096747 | I23: =(G23-G22)/G22 -> 0.012096753 | J23: -0.00011652922
A24: 40392 | B24: 55.999963 | C24: 57.699959 | D24: 55.919952 | E24: 57.529956 | F24: 17988000 | G24: 34.539765 | H24: =(E24-E23)/E23 -> 0.041832703 | I24: =(G24-G23)/G23 -> 0.041832703 | J24: 0.019915979
A25: 40393 | B25: 56.869952 | C25: 57.889959 | D25: 56.799955 | E25: 57.559955 | F25: 12997800 | G25: 34.557776 | H25: =(E25-E24)/E24 -> 0.00052145008 | I25: =(G25-G24)/G24 -> 0.00052145694 | J25: -0.0035599258 | L25: COP ALPHA | M25: =M19 -> -0.00011507642
A26: 40394 | B26: 57.549957 | C26: 58.029953 | D26: 57.049959 | E26: 57.419961 | F26: 13312800 | G26: 34.473726 | H26: =(E26-E25)/E25 -> -0.0024321423 | I26: =(G26-G25)/G25 -> -0.0024321588 | J26: 0.0041414288 | L26: COP BETA | M26: =M20 -> 1.1685959
A27: 40395 | B27: 56.999953 | C27: 57.819952 | D27: 56.87996 | E27: 57.699959 | F27: 11103600 | G27: 34.641832 | H27: =(E27-E26)/E26 -> 0.0048763182 | I27: =(G27-G26)/G26 -> 0.0048763513 | J27: -0.00051020606
A28: 40396 | B28: 57.039961 | C28: 57.539949 | D28: 56.239953 | E28: 56.929956 | F28: 12876900 | G28: 34.179538 | H28: =(E28-E27)/E27 -> -0.013344949 | I28: =(G28-G27)/G27 -> -0.013344964 | J28: -0.0020066454
A29: 40399 | B29: 57.249952 | C29: 57.569948 | D29: 57.089952 | E29: 57.309951 | F29: 8365100 | G29: 34.407679 | H29: =(E29-E28)/E28 -> 0.0066747812 | I29: =(G29-G28)/G28 -> 0.006674783 | J29: 0.0042418151
A30: 40400 | B30: 56.519952 | C30: 57.279952 | D30: 56.319959 | E30: 56.869952 | F30: 12286600 | G30: 34.143513 | H30: =(E30-E29)/E29 -> -0.0076775323 | I30: =(G30-G29)/G29 -> -0.0076775304 | J30: -0.005094053
A31: 40401 | B31: 55.95995 | C31: 55.999963 | D31: 55.19995 | E31: 55.509953 | F31: 13870600 | G31: 33.326998 | H31: =(E31-E30)/E30 -> -0.023914193 | I31: =(G31-G30)/G30 -> -0.023914206 | J31: -0.024935521
A32: 40402 | B32: 54.939958 | C32: 55.639954 | D32: 54.599951 | E32: 55.349957 | F32: 10271300 | G32: 33.23094 | H32: =(E32-E31)/E31 -> -0.0028822939 | I32: =(G32-G31)/G31 -> -0.0028822878 | J32: -0.0056730749
A33: 40403 | B33: 54.859963 | C33: 55.439956 | D33: 54.839956 | E33: 55.019963 | F33: 8487100 | G33: 33.032819 | H33: =(E33-E32)/E32 -> -0.0059619559 | I33: =(G33-G32)/G32 -> -0.0059619439 | J33: -0.0016278964
A34: 40406 | B34: 54.799959 | C34: 54.969957 | D34: 54.299961 | E34: 54.92996 | F34: 9422000 | G34: 32.978783 | H34: =(E34-E33)/E33 -> -0.0016358244 | I34: =(G34-G33)/G33 -> -0.0016358277 | J34: -0.00011070594
A35: 40407 | B35: 55.379957 | C35: 56.249961 | D35: 54.92996 | E35: 55.869962 | F35: 11578100 | G35: 33.54314 | H35: =(E35-E34)/E34 -> 0.017112738 | I35: =(G35-G34)/G34 -> 0.01711273 | J35: 0.010079571
A36: 40408 | B36: 55.859953 | C36: 55.929965 | D36: 54.919962 | E36: 55.419954 | F36: 7930300 | G36: 33.272965 | H36: =(E36-E35)/E35 -> -0.0080545607 | I36: =(G36-G35)/G35 -> -0.008054553 | J36: 0.00093124832
A37: 40409 | B37: 55.109962 | C37: 55.259954 | D37: 54.319962 | E37: 54.70996 | F37: 9833700 | G37: 32.8467 | H37: =(E37-E36)/E36 -> -0.012811162 | I37: =(G37-G36)/G36 -> -0.012811152 | J37: -0.013857186
A38: 40410 | B38: 54.289963 | C38: 54.469955 | D38: 53.289962 | E38: 53.889961 | F38: 12857700 | G38: 32.35439 | H38: =(E38-E37)/E37 -> -0.014988112 | I38: =(G38-G37)/G37 -> -0.014988111 | J38: -0.0056069188
... A1513: 42551 | B1513: 43.720001 | C1513: 44.119999 | D1513: 43.209999 | E1513: 43.599998 | F1513: 9342200 | G1513: 43.34066 | H1513: =(E1513-E1512)/E1512 -> -0.0070599408 | I1513: =(G1513-G1512)/G1512 -> -0.0070599392 | J1513: 0.013298378
H1514: =MIN(I3:I1513) -> -0.092115684 | I1514: =AVERAGE(I3:I1513) -> 0.00040281925
...

Sheet Dis
A1: Date | B1: Open | C1: High | D1: Low | E1: Close | F1: Volume | G1: Adj Close
A2: 40359 | B2: 32.16 | C2: 32.509998 | D2: 31.360001 | E2: 31.5 | F2: 17186400 | G2: 28.872496 | I2: Dis | J2: DJI
A3: 40360 | B3: 31.469999 | C3: 32.099998 | D3: 30.91 | E3: 31.49 | F3: 19906200 | G3: 28.86333 | H3: =(E3-E2)/E2 -> -0.00031746032 | I3: =(G3-G2)/G2 -> -0.00031746476 | J3: -0.0042448511 | L3: SUMMARY OUTPUT
A4: 40361 | B4: 31.559999 | C4: 31.68 | D4: 30.719999 | E4: 31.379999 | F4: 15597300 | G4: 28.762505 | H4: =(E4-E3)/E3 -> -0.0034932042 | I4: =(G4-G3)/G3 -> -0.0034931867 | J4: -0.0047315346
A5: 40365 | B5: 31.77 | C5: 32.299999 | D5: 31.379999 | E5: 31.719999 | F5: 15215500 | G5: 29.074145 | H5: =(E5-E4)/E4 -> 0.010834927 | I5: =(G5-G4)/G4 -> 0.010834939 | J5: 0.0058989071 | L5: Regression Statistics
A6: 40366 | B6: 31.73 | C6: 33.169998 | D6: 31.66 | E6: 33.139999 | F6: 14309500 | G6: 30.375698 | H6: =(E6-E5)/E5 -> 0.04476671 | I6: =(G6-G5)/G5 -> 0.044766682 | J6: 0.028188717 | L6: Multiple R | M6: 0.7493255
A7: 40367 | B7: 33.330002 | C7: 33.540001 | D7: 32.900002 | E7: 33.34 | F7: 10044000 | G7: 30.559017 | H7: =(E7-E6)/E6 -> 0.0060350334 | I7: =(G7-G6)/G6 -> 0.0060350547 | J7: 0.01204897 | L7: R Square | M7: 0.5614887
A8: 40368 | B8: 33.380001 | C8: 33.799999 | D8: 33.369999 | E8: 33.75 | F8: 8530900 | G8: 30.934817 | H8: =(E8-E7)/E7 -> 0.01229754 | I8: =(G8-G7)/G7 -> 0.012297516 | J8: 0.005823069 | L8: Adjusted R Square | M8: 0.56119811
A9: 40371 | B9: 33.580002 | C9: 33.889999 | D9: 33.389999 | E9: 33.77 | F9: 10094300 | G9: 30.953149 | H9: =(E9-E8)/E8 -> 0.00059259259 | I9: =(G9-G8)/G8 -> 0.00059260089 | J9: 0.0017885081 | L9: Standard Error | M9: 0.009097382
A10: 40372 | B10: 34.110001 | C10: 34.669998 | D10: 33.959999 | E10: 34.450001 | F10: 8653000 | G10: 31.576429 | H10: =(E10-E9)/E9 -> 0.020136245 | I10: =(G10-G9)/G9 -> 0.020136239 | J10: 0.014364343 | L10: Observations | M10: 1511
A11: 40373 | B11: 34.240002 | C11: 34.509998 | D11: 33.919998 | E11: 34.240002 | F11: 7955100 | G11: 31.383946 | H11: =(E11-E10)/E10 -> -0.0060957618 | I11: =(G11-G10)/G10 -> -0.0060957811 | J11: 0.00035705809
